# エラークラスの継承
[![Image from Gyazo](https://i.gyazo.com/d751aa03a86044849c7832545711d7e5.png)](https://gyazo.com/d751aa03a86044849c7832545711d7e5)

大元には Exseptionクラスがあり、そこから StandardErrorと 特殊なエラーたちに分かれる。  

⭐️ rescue節で特にエラーオブジェクトを指定しない場合は**StandardError**クラス配下を拾う。  
そのため特殊なエラーたちは引っかからないので、もし、全てのエラーを拾いたい場合  
rescue節に `rescue Exseption`と書けば特殊な方も拾われる。  
しかしこの書き方は推奨されないのであまり使わないように！！
***

# ⚠️ 継承関係と rescueの順番に注意する
例えば[複数の rescue](https://github.com/Tarara33/TIL/blob/main/Ruby/%E4%BE%8B%E5%A4%96%E5%87%A6%E7%90%86/%E8%A4%87%E6%95%B0%E3%81%AE%20rescue.md)を書いた場合、  
rescue節を書く順番を間違えるとずっと例外処理されなくなる場合がある。

例外が起きた時、エラークラスを上(Exseptionク)から順に探していく。  
なので上の図の NameErrorと　NoMethodErrorの親子関係を用いて実験すると
~~~
begin
  "abc".foo
rescue NameError => e
  puts "NameErrorの例外処理が実行されました"
  puts e.class
  puts e.message
rescue NoMethodError => e
  "NoMethodErrorの例外処理が実行されました"
  puts e.class
  puts e.message
end

【実行結果】
NameErrorの例外処理が実行されました
NoMethodError
undefined method `foo' for "abc":String
~~~
このように、NoMethodErrorクラスは親である NameErrorクラスに含まれるので、  
rescue節が当てはまるため、NameErrorクラスの例外処理が走る。

逆にすると NoMethodErrorクラスが走る。
~~~
begin
  "abc".foo
rescue NoMethodError => e
  puts "NoMethodErrorの例外処理が実行されました"
  puts e.class
  puts e.message
rescue NameError => e
  puts "NameErrorの例外処理が実行されました"
  puts e.class
  puts e.message
end

【実行結果】
NoMethodErrorの例外処理が実行されました
NoMethodError
undefined method `foo' for "abc":String
~~~
***
