# 例外処理の流れ
begin ~ resucue ~ endで囲っていないところで例外が起きた場合、  
そこで処理を中断して、メソッドの呼び出しを一つずつ戻っていき、その途中で例外処理のコードがあれば実行する。
~~~
def method1 
  puts "メソッド1を実行します"

  begin
    method2
  rescue 
    puts "例外が発生しました！"
  end
  
  puts "メソッド1を実行が終わりました"
end

def method2
  puts "メソッド2を実行します"
  method3
  puts "メソッド2を実行が終わりました"
end

def method3
  puts "メソッド3を実行します"
  # ZerroDivisionErrorを発生させる
  1 / 0
  puts "メソッド3を実行が終わりました"
end

# 処理を開始する
method1
=> 　メソッド1を実行します
=> メソッド2を実行します
=> メソッド3を実行します
=> 例外が発生しました！
=> メソッド1を実行が終わりました
~~~
このコードの処理の流れとしては、
1. メソッド1を実行して、メソッド2を呼び出す。
2. メソッド2を実行して、メソッド3を呼び出す。
3. メソッド3を実行して、例外が発生する。
4. メソッド3には例外処理のコードがないのでメソッド2に処理が戻る。
5. メソッド2には例外処理のコードがないのでメソッド1に処理が戻る。
6. メソッド1の例外処理を実行する。
7. そのままメソッド1の残りの処理を実行する。

もしメソッド1にも例外処理がなければ、メソッドを全て遡っても例外処理がないので、  
メソッド3の ZerroDivisionErrorが発生され、終わる。
***

***
